Workbook

Sheet Storico
A1: The Coca-Cola Company (KO) – DCF Model
A2: Historical data from the FY2025 and FY2023 Form 10-K · $ millions unless stated otherwise · Valuation date: December 31, 2025
A4: INCOME STATEMENT ($ mm) | B4: 2023 | C4: 2024 | D4: 2025
A5: Net operating revenues | B5: 45754 | C5: 47061 | D5: 47941
A6: Cost of goods sold | B6: 18520 | C6: 18324 | D6: 18397
A7: Gross profit | B7: =B5-B6 -> 27234 | C7: =C5-C6 -> 28737 | D7: =D5-D6 -> 29544
A8: Gross margin % | B8: =B7/B5 -> 0.59522665 | C8: =C7/C5 -> 0.61063301 | D8: =D7/D5 -> 0.61625748
A9: Selling, general & administrative expenses (SG&A) | B9: 13972 | C9: 14582 | D9: 14521
A10: Other operating charges | B10: 1951 | C10: 4163 | D10: 1261
A11: Operating income (EBIT, computed) | B11: =B7-B9-B10 -> 11311 | C11: =C7-C9-C10 -> 9992 | D11: =D7-D9-D10 -> 13762
A12: Operating margin % | B12: =B11/B5 -> 0.24721336 | C12: =C11/C5 -> 0.21232018 | D12: =D11/D5 -> 0.28706118
A13: Operating income as reported (check) | B13: 11311 | C13: 9992 | D13: 13762
A14: Difference (must be 0) | B14: =B11-B13 -> 0 | C14: =C11-C13 -> 0 | D14: =D11-D13 -> 0
A15: Interest income | B15: 907 | C15: 988 | D15: 786
A16: Interest expense | B16: 1527 | C16: 1656 | D16: 1654
A17: Equity income (loss) – net | B17: 1691 | C17: 1770 | D17: 2031
A18: Other income (loss) – net | B18: 570 | C18: 1992 | D18: 1073
A19: Income before income taxes | B19: =B11+B15-B16+B17+B18 -> 12952 | C19: =C11+C15-C16+C17+C18 -> 13086 | D19: =D11+D15-D16+D17+D18 -> 15998
A20: Income taxes | B20: 2249 | C20: 2437 | D20: 2861
A21: Effective tax rate | B21: =B20/B19 -> 0.17364114 | C21: =C20/C19 -> 0.18622956 | D21: =D20/D19 -> 0.17883485
A22: Consolidated net income | B22: =B19-B20 -> 10703 | C22: =C19-C20 -> 10649 | D22: =D19-D20 -> 13137
A23: Diluted weighted-average shares (mm) | B23: 4339 | C23: 4320 | D23: 4313
A25: CASH FLOW STATEMENT ($ mm) | B25: 2023 | C25: 2024 | D25: 2025
A26: Depreciation & amortization (D&A) | B26: 1128 | C26: 1075 | D26: 1050
A27: Stock-based compensation (SBC) | B27: 254 | C27: 286 | D27: 279
A28: Net cash provided by operating activities | B28: 11599 | C28: 6805 | D28: 7408
A29: Capital expenditures (purchases of PP&E) | B29: 1852 | C29: 2064 | D29: 2112
A30: Simple free cash flow (CFO – CapEx) | B30: =B28-B29 -> 9747 | C30: =C28-C29 -> 4741 | D30: =D28-D29 -> 5296
A31: CapEx % of revenue | B31: =B29/B5 -> 0.040477335 | C31: =C29/C5 -> 0.043857972 | D31: =D29/D5 -> 0.04405415
A32: D&A % of revenue | B32: =B26/B5 -> 0.024653582 | C32: =C26/C5 -> 0.022842694 | D32: =D26/D5 -> 0.021901921
A33: Dividends paid | B33: 7952 | C33: 8359 | D33: 8779
A34: Purchases of treasury stock | B34: 2289 | C34: 1795 | D34: 746
A36: BALANCE SHEET ($ mm) | B36: 2023 | C36: 2024 | D36: 2025
A37: Cash and cash equivalents | B37: 9366 | C37: 10828 | D37: 10270
A38: Short-term investments | B38: 2997 | C38: 2020 | D38: 3602
A39: Marketable securities | B39: 1300 | C39: 1723 | D39: 1934
A40: Trade accounts receivable | B40: 3410 | C40: 3569 | D40: 3038
A41: Inventories | B41: 4424 | C41: 4728 | D41: 4425
A42: Prepaid expenses & other current assets | B42: 5235 | C42: 2998 | D42: 2433
A43: Assets held for sale | B43: 0 | C43: 131 | D43: 5342
...

Sheet Analysis
A1: hist analysis ($mm) | B1: 2023 | C1: 2024 | D1: 2025
A2: Revenues | B2: =Storico!B5 -> 45754 | C2: =Storico!C5 -> 47061 | D2: =Storico!D5 -> 47941
A3: revenue growth | C3: =C2/B2-1 -> 0.028565808 | D3: =D2/C2-1 -> 0.018699135
A4: CAGR 2023-2025 | B4: =(D2/B2)^(1/(D1-B1))-1 -> 0.023620584
A5: Gross margin | B5: =Storico!B7/B2 -> 0.59522665 | C5: =Storico!C7/C2 -> 0.61063301 | D5: =Storico!D7/D2 -> 0.61625748
A6: SG&A % of revenue | B6: =Storico!B9/B2 -> 0.30537221 | C6: =Storico!C9/C2 -> 0.30985317 | D6: =Storico!D9/D2 -> 0.30289314
A7: Adjusted EBIT | B7: =Storico!B7-Storico!B9 -> 13262 | C7: =Storico!C7-Storico!C9 -> 14155 | D7: =Storico!D7-Storico!D9 -> 15023
A8: Adjusted EBIT margin % | B8: =B7/B2 -> 0.28985444 | C8: =C7/C2 -> 0.30077984 | D8: =D7/D2 -> 0.31336434
A10: Fairlife contingent consideration | B10: 0 | C10: 6126 | D10: 0
A11: Operating NWC ($mm) | B11: =Storico!B40+Storico!B41-Storico!B46-Storico!B50+Storico!B42 -> -3985 | C11: =Storico!C40+Storico!C41-Storico!C46-Storico!C50+Storico!C42 -> -11804 | D11: =Storico!D40+Storico!D41-Storico!D46-Storico!D50+Storico!D42 -> -5442
A12: Adjusted Operating NWC ($mm) | B12: =B11+B10 -> -3985 | C12: =C11+C10 -> -5678 | D12: =D11+D10 -> -5442
A13: Change in Adjusted NWC ($MM) | C13: =C12-B12 -> -1693 | D13: =D12-C12 -> 236
A14: Adjusted NWC % of revenue | B14: =B12/B2 -> -0.08709621 | C14: =C12/C2 -> -0.12065192 | D14: =D12/D2 -> -0.11351453
A15: NWC group A | B15: =Storico!B40+Storico!B41-Storico!B47 -> 2244 | C15: =Storico!C40+Storico!C41-Storico!C47 -> 2829 | D15: =Storico!D40+Storico!D41-Storico!D47 -> 1814
A16: NWC group B | B16: =B12-B15 -> -6229 | C16: =C12-C15 -> -8507 | D16: =D12-D15 -> -7256
A17: NWC group B % revenues | B17: =B16/B2 -> -0.1361411 | C17: =C16/C2 -> -0.18076539 | D17: =D16/D2 -> -0.1513527 | E17: NWC group B % revenues average | F17: =AVERAGE(B17:D17) -> -0.1560864
A18: DSO | B18: =Storico!B40/Analysis!B2*365 -> 27.203086 | C18: =Storico!C40/Analysis!C2*365 -> 27.680776 | D18: =Storico!D40/Analysis!D2*365 -> 23.129889 | E18: DSO average | F18: =AVERAGE(B18:D18) -> 26.004584
A19: DIO | B19: =Storico!B41/Storico!B6*365 -> 87.190065 | C19: =Storico!C41/Storico!C6*365 -> 94.178127 | D19: =Storico!D41/Storico!D6*365 -> 87.792847 | E19: DIO average | F19: =AVERAGE(B19:D19) -> 89.720346
A20: DPO | B20: =Storico!B47/Storico!B6*365 -> 110.17009 | C20: =Storico!C47/Storico!C6*365 -> 108.91836 | D20: =Storico!D47/Storico!D6*365 -> 112.07724 | E20: DPO average | F20: =AVERAGE(B20:D20) -> 110.38856

Sheet DCF
A1: Coca-Cola - Base Case ($mm) | B1: 2023A | C1: 2024A | D1: 2025A | E1: 2026E | F1: 2027E | G1: 2028E | H1: 2029E | I1: 2030E
A2: Revenue | B2: =Storico!B5 -> 45754 | C2: =Storico!C5 -> 47061 | D2: =Storico!D5 -> 47941 | E2: =D2*(1+E3) -> 49858.64 | F2: =E2*(1+F3) -> 51653.551 | G2: =F2*(1+G3) -> 53306.465 | H2: =G2*(1+H3) -> 54799.046 | I2: =H2*(1+I3) -> 56114.223
A3: revenue growth % | C3: =C2/B2-1 -> 0.028565808 | D3: =D2/C2-1 -> 0.018699135 | E3: 0.04 | F3: 0.036 | G3: 0.032 | H3: 0.028 | I3: 0.024
A4: Cost of goods sold | B4: =Storico!B6 -> 18520 | C4: =Storico!C6 -> 18324 | D4: =Storico!D6 -> 18397
A5: Gross profit | B5: =Storico!B7 -> 27234 | C5: =Storico!C7 -> 28737 | D5: =Storico!D7 -> 29544 | E5: =E6*E2 -> 30663.064 | F5: =F6*F2 -> 31766.934 | G5: =G6*G2 -> 32783.476 | H5: =H6*H2 -> 33701.413 | I5: =I6*I2 -> 34510.247
A6: gross margin | B6: =B5/B2 -> 0.59522665 | C6: =C5/C2 -> 0.61063301 | D6: =D5/D2 -> 0.61625748 | E6: 0.615 | F6: 0.615 | G6: 0.615 | H6: 0.615 | I6: 0.615
A7: SG&A | B7: =Storico!B9 -> 13972 | C7: =Storico!C9 -> 14582 | D7: =Storico!D9 -> 14521 | E7: =E8*E2 -> 15258.714 | F7: =F8*F2 -> 15808.027 | G7: =G8*G2 -> 16313.884 | H7: =H8*H2 -> 16770.673 | I7: =I8*I2 -> 17173.169
A8: SG&A % of revenue | B8: =B7/B2 -> 0.30537221 | C8: =C7/C2 -> 0.30985317 | D8: =D7/D2 -> 0.30289314 | E8: =AVERAGE($B$8:$D$8) -> 0.30603951 | F8: =AVERAGE($B$8:$D$8) -> 0.30603951 | G8: =AVERAGE($B$8:$D$8) -> 0.30603951 | H8: =AVERAGE($B$8:$D$8) -> 0.30603951 | I8: =AVERAGE($B$8:$D$8) -> 0.30603951
A9: Adjusted EBIT | B9: =B5-B7 -> 13262 | C9: =C5-C7 -> 14155 | D9: =D5-D7 -> 15023 | E9: =E5-E7 -> 15404.35 | F9: =F5-F7 -> 15958.907 | G9: =G5-G7 -> 16469.592 | H9: =H5-H7 -> 16930.74 | I9: =I5-I7 -> 17337.078
A10: Adjusted EBIT margin % | B10: =B9/B2 -> 0.28985444 | C10: =C9/C2 -> 0.30077984 | D10: =D9/D2 -> 0.31336434 | E10: =E9/E2 -> 0.30896049 | F10: =F9/F2 -> 0.30896049 | G10: =G9/G2 -> 0.30896049 | H10: =H9/H2 -> 0.30896049 | I10: =I9/I2 -> 0.30896049
A12: Tax rate % | E12: 0.209 | F12: 0.209 | G12: 0.209 | H12: 0.209 | I12: 0.209
A13: Taxes on EBIT | E13: =E12*E9 -> 3219.5092 | F13: =F12*F9 -> 3335.4115 | G13: =G12*G9 -> 3442.1447 | H13: =H12*H9 -> 3538.5247 | I13: =I12*I9 -> 3623.4493
A14: NOPAT | E14: =E9-E13 -> 12184.841 | F14: =F9-F13 -> 12623.495 | G14: =G9-G13 -> 13027.447 | H14: =H9-H13 -> 13392.216 | I14: =I9-I13 -> 13713.629
A15: CAPEX % of revenue | B15: =Storico!B31 -> 0.040477335 | C15: =Storico!C31 -> 0.043857972 | D15: =Storico!D31 -> 0.04405415 | E15: 0.044 | F15: 0.0425 | G15: 0.0405 | H15: 0.039 | I15: 0.0375
A16: CAPEX | B16: =B15*B2 -> 1852 | C16: =C15*C2 -> 2064 | D16: =D15*D2 -> 2112 | E16: =E15*E2 -> 2193.7802 | F16: =F15*F2 -> 2195.2759 | G16: =G15*G2 -> 2158.9118 | H16: =H15*H2 -> 2137.1628 | I16: =I15*I2 -> 2104.2834
A17: D&A % of revenue | B17: =Storico!B32 -> 0.024653582 | C17: =Storico!C32 -> 0.022842694 | D17: =Storico!D32 -> 0.021901921 | E17: 0.0235 | F17: 0.0255 | G17: 0.0276 | H17: 0.0298 | I17: 0.032
A18: D&A | B18: =B17*B2 -> 1128 | C18: =C17*C2 -> 1075 | D18: =D17*D2 -> 1050 | E18: =E17*E2 -> 1171.678 | F18: =F17*F2 -> 1317.1656 | G18: =G17*G2 -> 1471.2584 | H18: =H17*H2 -> 1633.0116 | I18: =I17*I2 -> 1795.6551
A19: NWC group A | B19: =Analysis!B15 -> 2244 | C19: =Analysis!C15 -> 2829 | D19: =Analysis!D15 -> 1814 | E19: =Analysis!$F$18*DCF!E2/365+Analysis!$F$19*(DCF!E2-DCF!E5)/365-Analysis!$F$20*(DCF!E2-DCF!E5)/365 -> 2465.2462 | F19: =Analysis!$F$18*DCF!F2/365+Analysis!$F$19*(DCF!F2-DCF!F5)/365-Analysis!$F$20*(DCF!F2-DCF!F5)/365 -> 2553.9951 | G19: =Analysis!$F$18*DCF!G2/365+Analysis!$F$19*(DCF!G2-DCF!G5)/365-Analysis!$F$20*(DCF!G2-DCF!G5)/365 -> 2635.7229 | H19: =Analysis!$F$18*DCF!H2/365+Analysis!$F$19*(DCF!H2-DCF!H5)/365-Analysis!$F$20*(DCF!H2-DCF!H5)/365 -> 2709.5231 | I19: =Analysis!$F$18*DCF!I2/365+Analysis!$F$19*(DCF!I2-DCF!I5)/365-Analysis!$F$20*(DCF!I2-DCF!I5)/365 -> 2774.5517
A20: NWC group B | B20: =Analysis!B16 -> -6229 | C20: =Analysis!C16 -> -8507 | D20: =Analysis!D16 -> -7256 | E20: =Analysis!$F$17*DCF!E2 -> -7782.2556 | F20: =Analysis!$F$17*DCF!F2 -> -8062.4168 | G20: =Analysis!$F$17*DCF!G2 -> -8320.4141 | H20: =Analysis!$F$17*DCF!H2 -> -8553.3857 | I20: =Analysis!$F$17*DCF!I2 -> -8758.667
A21: NWC | B21: =B19+B20 -> -3985 | C21: =C19+C20 -> -5678 | D21: =D19+D20 -> -5442 | E21: =E19+E20 -> -5317.0094 | F21: =F19+F20 -> -5508.4217 | G21: =G19+G20 -> -5684.6912 | H21: =H19+H20 -> -5843.8626 | I21: =I19+I20 -> -5984.1153
A22: Change in NWC | C22: =C21-B21 -> -1693 | D22: =D21-C21 -> 236 | E22: =E21-D21 -> 124.99062 | F22: =F21-E21 -> -191.41234 | G22: =G21-F21 -> -176.26949 | H22: =H21-G21 -> -159.17135 | I22: =I21-H21 -> -140.2527
A24: WACC | B24: =WACC!B15 -> 0.065812397
A25: g | B25: 0.02 | J25: TV
A26: Unlevered Free Cash Flow (FCFF) | E26: =E14+E18-E16-E22 -> 11037.748 | F26: =F14+F18-F16-F22 -> 11936.797 | G26: =G14+G18-G16-G22 -> 12516.063 | H26: =H14+H18-H16-H22 -> 13047.236 | I26: =I14+I18-I16-I22 -> 13545.253 | J26: =I26*(1+B25)/(B24-B25) -> 301581.21
A27: % margin | E27: =E26/E2 -> 0.22138085 | F27: =F26/F2 -> 0.23109345 | G27: =G26/G2 -> 0.23479447 | H27: =H26/H2 -> 0.23809239 | I27: =I26/I2 -> 0.24138717
A28: discount period | E28: 0.5 | F28: =E28+1 -> 1.5 | G28: =F28+1 -> 2.5 | H28: =G28+1 -> 3.5 | I28: =H28+1 -> 4.5 | J28: =I28 -> 4.5
A29: discount factor | E29: =1/(1+$B$24)^E28 -> 0.96863379 | F29: =1/(1+$B$24)^F28 -> 0.90882204 | G29: =1/(1+$B$24)^G28 -> 0.85270357 | H29: =1/(1+$B$24)^H28 -> 0.80005034 | I29: =1/(1+$B$24)^I28 -> 0.75064837 | J29: =1/(1+$B$24)^J28 -> 0.75064837
A30: PV of FCFF and TV | E30: =E26*E29 -> 10691.536 | F30: =F26*F29 -> 10848.424 | G30: =G26*G29 -> 10672.492 | H30: =H26*H29 -> 10438.445 | I30: =I26*I29 -> 10167.722 | J30: =J26*J29 -> 226381.45
A32: Enterprise Value | B32: =SUM(E30:J30) -> 279200.07
A33: % TV on EV | B33: =J30/B32 -> 0.81082161
A34: net debt | B34: =WACC!E6-Storico!D37-Storico!D38-Storico!D39 -> 29686
A35: noncontrolling interests | B35: =Storico!D53 -> 2106
A36: equity method investments | B36: =Storico!D44 -> 20235
A37: Equity Value | B37: =B32-B34-B35+B36 -> 267643.07
A38: outstanding stock options | B38: 27
A39: average exercise price | B39: 55.74
A40: n. of shares from options | B40: =MAX(0,B38*(1-B39/B45)) -> 5.4726076
A41: PSU | B41: 2.62
A42: RSU | B42: 4.536
A43: Number of Shares | B43: =SUM(B40:B42,Storico!D59) -> 4314.6286
...

Sheet WACC
A1: Ke | B1: =H1+E1*N1 -> 0.070307953 | D1: levered beta | E1: =E2*(1+(1-K1)*E7) -> 0.64524558 | G1: rf | H1: 0.04153 | J1: marginal tax rate | K1: 0.2563 | M1: equity risk premium | N1: 0.0446
D2: unlevered beta corrected for cash | E2: 0.58
D3: price stock 12/31 | E3: 69.91
D4: shares | E4: =Storico!D59 -> 4302
D5: market cap | E5: =E3*E4 -> 300752.82
D6: gross debt | E6: =Storico!D48+Storico!D49+Storico!D52 -> 45492
D7: D/E | E7: =E6/E5 -> 0.15126043
A9: Kd after tax | B9: =E9*(1-K1) -> 0.036091761 | D9: Kd pre-tax | E9: =H1+B13 -> 0.04853
A10: interest coverage ratio | B10: =Storico!D11/Storico!D16 -> 8.3204353
A11: spread sintetico | B11: 0.0055
A12: rating | B12: A1/A+
A13: spread reale | B13: 0.007 | C13: equity weight | D13: =E5/(E6+E5) -> 0.8686132
C14: debt weight | D14: =E6/(E5+E6) -> 0.1313868
A15: WACC | B15: =B1*D13+B9*D14 -> 0.065812397
